<robot name="cython_robot_model">
  <link name="world"/>

  <joint name="object_joint" type="floating" >
    <axis xyz="0 0 1" />
    <parent link="world" />
    <child link="base_link" />
    <origin xyz="0 0 1" rpy="0 0 0" />
  </joint>

  <link name="base_link">
    <inertial>
      <origin xyz="0 0 0" />
      <mass value="10.0" />
      <inertia  ixx="1.0" ixy="0.0"  ixz="0.0"  iyy="1.0"  iyz="0.0"  izz="1.0" />
    </inertial>
    
    <visual>
    <origin xyz="0 0 0.05" rpy="0 0 0"/>
      <geometry>
        <box size="0.2 .2 .1"/>
      </geometry>
      <material name="dark_gray">
            <color rgba=".1 .1 .1 1"/>
     </material>
    </visual>
    
    <collision>
      <origin xyz="0 0 0.05" rpy="0 0 0" />
 		<geometry>
        <box size="0.2 .2 .1"/>
      </geometry>
    </collision>
  </link>
  
<!---- shoulders -->
  <link name="shoulder_link">
    <inertial>
      <origin xyz="0 0 0" /> 
      <mass value="1.0" />
      <inertia  ixx="1.0" ixy="0.0"  ixz="0.0"  iyy="1.0"  iyz="0.0"  izz="1.0" />
    </inertial>
    
    <visual>
      <origin xyz="0 0 0.25" rpy="0 0 0"/>
      <geometry>
        <box size="0.04 0.04 0.5"/>
      </geometry>
       <material name="gray">
            <color rgba=".5 .5 .5 1"/>
     </material>
    </visual>
    
    <collision>
      <origin xyz="0 0 0.25" rpy="0 0 0"/>
      <geometry>
        <box size="0.04 0.04 0.5"/>
      </geometry>
    </collision>
  </link>
  
  <joint name="shoulder" type="revolute">
    <limit effort="1000.0" lower="0.0" upper="0.548" velocity="0.05"/>
    <parent link="base_link"/>
    <child link="shoulder_link"/>
    <axis xyz="0 0 1"/>
    <origin xyz="0 0 0.1" rpy="0 0 0"/>
  </joint>
  
  
  <!---- elbow -->
    <link name="elbow_link">
    <inertial>
      <origin xyz="0 0 0" /> 
      <mass value="0.5" />
      <inertia  ixx="1.0" ixy="0.0"  ixz="0.0"  iyy="1.0"  iyz="0.0"  izz="1.0" />
    </inertial>
    
    <visual>
      <origin xyz="0 0 0.15" rpy="0 0 0"/>
      <geometry>
        <box size="0.02 0.02 0.3"/>
      </geometry>
      <material name="blue">
            <color rgba="0 0 .4 1"/>
     </material>
    </visual>
    
    <collision>
      <origin xyz="0 0 0.15" rpy="0 0 0"/>
      <geometry>
        <box size="0.02 0.02 0.3"/>
      </geometry>
    </collision>
  </link>
  
   <joint name="elbow" type="revolute">
    <limit effort="1000.0" lower="0.0" upper="0.548" velocity="0.05"/>
    <parent link="shoulder_link"/>
    <child link="elbow_link"/>
    <axis xyz="0 1 0"/>
    <origin xyz="0 0.031 0.5" rpy="0 0 0"/>
  </joint>
  
  <!---- wrist -->
   <link name="wrist_link">
    <inertial>
      <origin xyz="0 0 0" /> 
      <mass value="0.25" />
      <inertia  ixx="1.0" ixy="0.0"  ixz="0.0"  iyy="1.0"  iyz="0.0"  izz="1.0" />
    </inertial>
    
   <visual>
      <origin xyz="0 0 0.15" rpy="0 0 0"/>
      <geometry>
        <box size="0.005 0.005 0.3"/>
      </geometry>
       <material name="green">
            <color rgba="0 1 0 1"/>
     </material>
    </visual>
    
    <collision>
      <origin xyz="0 0 0.15" rpy="0 0 0"/>
      <geometry>
        <box size="0.005 0.005 0.3"/>
      </geometry>
    </collision>
  </link>
  
   <joint name="wrist" type="revolute">
    <limit effort="1000.0" lower="0.0" upper="0.548" velocity="0.05"/>
    <parent link="elbow_link"/>
    <child link="wrist_link"/>
    <axis xyz="0 1 0"/>
    <origin xyz="0 0.0135 0.3" rpy="0 0 0"/>
  </joint>
  
  
  <gazebo reference="shoulder_link">
       <material>Gazebo/Blue</material>
      <!-- <turnGravityOff>true</turnGravityOff>-->
  </gazebo>
  
  <gazebo reference="elbow_link">
       <material>Gazebo/Green</material>
      <!-- <turnGravityOff>true</turnGravityOff>-->
  </gazebo>
  
  <gazebo reference="base_link">
       <material>Gazebo/Red</material>
       <!-- <turnGravityOff>true</turnGravityOff>-->
  </gazebo>
  
  <gazebo reference="wrist_link">
       <material>Gazebo/White</material>
       <!-- <turnGravityOff>true</turnGravityOff>-->
  </gazebo>

</robot>

